Workbook
Name Slicer_Year: #N/A

Sheet Dataset for Data Analytics - cl
A1: OrderID | B1: Date | C1: Year | D1: Quarter | E1: CustomerID | F1: Product | G1: Quantity | H1: UnitPrice | I1: ShippingAddress | J1: PaymentMethod | K1: OrderStatus | L1: TrackingNumber | M1: ItemsInCart | N1: CouponCode | O1: ReferralSource | P1: TotalPrice | Q1: TotalRevenue | R1: Outliers
A2: ORD200000 | B2: 44930 | C2: 2023 | D2: Q1 | E2: C72649 | F2: Monitor | G2: 5 | H2: 570.62 | I2: 928 Main St | J2: Debit Card | K2: Shipped | L2: TRK37947903 | M2: 7 | N2: SAVE10 | O2: Instagram | P2: 2853.1 | Q2: 2853.1 | R2: =IF(OR(P2<Outliers!$B$5, P2>Outliers!$B$6), "outliers", "")
A3: ORD200001 | B3: 45527 | C3: 2024 | D3: Q3 | E3: C75739 | F3: Phone | G3: 2 | H3: 151.35 | I3: 823 Main St | J3: Online | K3: Shipped | L3: TRK91186779 | M3: 3 | N3: SAVE10 | O3: Referral | P3: 302.7 | Q3: 302.7 | R3: =IF(OR(P3<Outliers!$B$5, P3>Outliers!$B$6), "outliers", "") | U3: =SUM(P2:P1201) -> 1264762
A4: ORD200002 | B4: 45349 | C4: 2024 | D4: Q1 | E4: C81728 | F4: Tablet | G4: 5 | H4: 550.68 | I4: 512 Main St | J4: Credit Card | K4: Cancelled | L4: TRK42903982 | M4: 8 | N4: FREESHIP | O4: Email | P4: 2753.4 | Q4: 2753.4 | R4: =IF(OR(P4<Outliers!$B$5, P4>Outliers!$B$6), "outliers", "") | S4: =COUNTIF(R2:R1200, "outliers") -> 8 | U4: =COUNT(P2:P1201) -> 1200
A5: ORD200003 | B5: 45214 | C5: 2023 | D5: Q4 | E5: C33540 | F5: Chair | G5: 1 | H5: 273.19 | I5: 275 Main St | J5: Debit Card | K5: Returned | L5: TRK62788070 | M5: 5 | N5: SAVE10 | O5: Facebook | P5: 273.19 | Q5: 273.19 | R5: =IF(OR(P5<Outliers!$B$5, P5>Outliers!$B$6), "outliers", "")
A6: ORD200004 | B6: 45785 | C6: 2025 | D6: Q2 | E6: C81840 | F6: Printer | G6: 4 | H6: 626.01 | I6: 668 Main St | J6: Online | K6: Delivered | L6: TRK29241424 | M6: 8 | N6: SAVE10 | O6: Email | P6: 2504.04 | Q6: 2504.04 | R6: =IF(OR(P6<Outliers!$B$5, P6>Outliers!$B$6), "outliers", "")
A7: ORD200005 | B7: 45222 | C7: 2023 | D7: Q4 | E7: C37249 | F7: Phone | G7: 2 | H7: 245.86 | I7: 934 Main St | J7: Credit Card | K7: Shipped | L7: TRK72976927 | M7: 4 | N7: SAVE10 | O7: Instagram | P7: 491.72 | Q7: 491.72 | R7: =IF(OR(P7<Outliers!$B$5, P7>Outliers!$B$6), "outliers", "")
A8: ORD200006 | B8: 45825 | C8: 2025 | D8: Q2 | E8: C83492 | F8: Laptop | G8: 1 | H8: 664.42 | I8: 986 Main St | J8: Gift Card | K8: Returned | L8: TRK96417362 | M8: 6 | N8: SAVE10 | O8: Facebook | P8: 664.42 | Q8: 664.42 | R8: =IF(OR(P8<Outliers!$B$5, P8>Outliers!$B$6), "outliers", "")
A9: ORD200007 | B9: 45058 | C9: 2023 | D9: Q2 | E9: C41460 | F9: Monitor | G9: 5 | H9: 149.55 | I9: 706 Main St | J9: Cash | K9: Shipped | L9: TRK78809193 | M9: 9 | N9: FREESHIP | O9: Facebook | P9: 747.75 | Q9: 747.75 | R9: =IF(OR(P9<Outliers!$B$5, P9>Outliers!$B$6), "outliers", "")
A10: ORD200008 | B10: 45749 | C10: 2025 | D10: Q2 | E10: C26817 | F10: Phone | G10: 2 | H10: 134.28 | I10: 904 Main St | J10: Gift Card | K10: Cancelled | L10: TRK61042692 | M10: 2 | O10: Email | P10: 268.56 | Q10: 268.56 | R10: =IF(OR(P10<Outliers!$B$5, P10>Outliers!$B$6), "outliers", "")
A11: ORD200009 | B11: 45251 | C11: 2023 | D11: Q4 | E11: C31946 | F11: Desk | G11: 4 | H11: 509.38 | I11: 102 Main St | J11: Credit Card | K11: Shipped | L11: TRK33478363 | M11: 6 | N11: SAVE10 | O11: Google | P11: 2037.52 | Q11: 2037.52 | R11: =IF(OR(P11<Outliers!$B$5, P11>Outliers!$B$6), "outliers", "")
A12: ORD200010 | B12: 45289 | C12: 2023 | D12: Q4 | E12: C43443 | F12: Tablet | G12: 5 | H12: 625.97 | I12: 333 Main St | J12: Credit Card | K12: Returned | L12: TRK98859248 | M12: 9 | N12: WINTER15 | O12: Instagram | P12: 3129.85 | Q12: 3129.85 | R12: =IF(OR(P12<Outliers!$B$5, P12>Outliers!$B$6), "outliers", "")
A13: ORD200011 | B13: 45339 | C13: 2024 | D13: Q1 | E13: C93861 | F13: Monitor | G13: 3 | H13: 49.14 | I13: 831 Main St | J13: Online | K13: Returned | L13: TRK48234646 | M13: 7 | N13: SAVE10 | O13: Email | P13: 147.42 | Q13: 147.42 | R13: =IF(OR(P13<Outliers!$B$5, P13>Outliers!$B$6), "outliers", "")
A14: ORD200012 | B14: 45580 | C14: 2024 | D14: Q4 | E14: C38785 | F14: Monitor | G14: 2 | H14: 180.5 | I14: 179 Main St | J14: Debit Card | K14: Pending | L14: TRK20419991 | M14: 6 | N14: FREESHIP | O14: Referral | P14: 361 | Q14: 361 | R14: =IF(OR(P14<Outliers!$B$5, P14>Outliers!$B$6), "outliers", "")
A15: ORD200013 | B15: 45168 | C15: 2023 | D15: Q3 | E15: C88348 | F15: Laptop | G15: 3 | H15: 201.49 | I15: 903 Main St | J15: Credit Card | K15: Returned | L15: TRK81913874 | M15: 4 | N15: FREESHIP | O15: Facebook | P15: 604.47 | Q15: 604.47 | R15: =IF(OR(P15<Outliers!$B$5, P15>Outliers!$B$6), "outliers", "")
A16: ORD200014 | B16: 45012 | C16: 2023 | D16: Q1 | E16: C98474 | F16: Tablet | G16: 2 | H16: 393.33 | I16: 980 Main St | J16: Debit Card | K16: Pending | L16: TRK79186539 | M16: 3 | N16: SAVE10 | O16: Instagram | P16: 786.66 | Q16: 786.66 | R16: =IF(OR(P16<Outliers!$B$5, P16>Outliers!$B$6), "outliers", "")
A17: ORD200015 | B17: 45124 | C17: 2023 | D17: Q3 | E17: C39416 | F17: Printer | G17: 1 | H17: 473.96 | I17: 942 Main St | J17: Cash | K17: Delivered | L17: TRK54930938 | M17: 3 | O17: Google | P17: 473.96 | Q17: 473.96 | R17: =IF(OR(P17<Outliers!$B$5, P17>Outliers!$B$6), "outliers", "")
A18: ORD200016 | B18: 44950 | C18: 2023 | D18: Q1 | E18: C28976 | F18: Printer | G18: 2 | H18: 533.81 | I18: 914 Main St | J18: Credit Card | K18: Pending | L18: TRK13194259 | M18: 3 | N18: FREESHIP | O18: Email | P18: 1067.62 | Q18: 1067.62 | R18: =IF(OR(P18<Outliers!$B$5, P18>Outliers!$B$6), "outliers", "")
A19: ORD200017 | B19: 45353 | C19: 2024 | D19: Q1 | E19: C60672 | F19: Tablet | G19: 1 | H19: 423.4 | I19: 382 Main St | J19: Debit Card | K19: Shipped | L19: TRK11972116 | M19: 3 | O19: Referral | P19: 423.4 | Q19: 423.4 | R19: =IF(OR(P19<Outliers!$B$5, P19>Outliers!$B$6), "outliers", "")
A20: ORD200018 | B20: 45742 | C20: 2025 | D20: Q1 | E20: C84329 | F20: Desk | G20: 1 | H20: 431.44 | I20: 891 Main St | J20: Gift Card | K20: Pending | L20: TRK65191045 | M20: 3 | N20: SAVE10 | O20: Facebook | P20: 431.44 | Q20: 431.44 | R20: =IF(OR(P20<Outliers!$B$5, P20>Outliers!$B$6), "outliers", "")
A21: ORD200019 | B21: 44949 | C21: 2023 | D21: Q1 | E21: C14552 | F21: Monitor | G21: 5 | H21: 224 | I21: 273 Main St | J21: Cash | K21: Returned | L21: TRK59101365 | M21: 9 | N21: SAVE10 | O21: Google | P21: 1120 | Q21: 1120 | R21: =IF(OR(P21<Outliers!$B$5, P21>Outliers!$B$6), "outliers", "")
A22: ORD200020 | B22: 45054 | C22: 2023 | D22: Q2 | E22: C54829 | F22: Chair | G22: 5 | H22: 62.51 | I22: 587 Main St | J22: Cash | K22: Pending | L22: TRK16718651 | M22: 9 | N22: WINTER15 | O22: Instagram | P22: 312.55 | Q22: 312.55 | R22: =IF(OR(P22<Outliers!$B$5, P22>Outliers!$B$6), "outliers", "")
A23: ORD200021 | B23: 45613 | C23: 2024 | D23: Q4 | E23: C99023 | F23: Monitor | G23: 4 | H23: 342.95 | I23: 569 Main St | J23: Cash | K23: Delivered | L23: TRK52646983 | M23: 6 | O23: Google | P23: 1371.8 | Q23: 1371.8 | R23: =IF(OR(P23<Outliers!$B$5, P23>Outliers!$B$6), "outliers", "")
A24: ORD200022 | B24: 44955 | C24: 2023 | D24: Q1 | E24: C34416 | F24: Monitor | G24: 2 | H24: 49.62 | I24: 633 Main St | J24: Online | K24: Pending | L24: TRK75937350 | M24: 2 | N24: SAVE10 | O24: Google | P24: 99.24 | Q24: 99.24 | R24: =IF(OR(P24<Outliers!$B$5, P24>Outliers!$B$6), "outliers", "")
A25: ORD200023 | B25: 45756 | C25: 2025 | D25: Q2 | E25: C42372 | F25: Phone | G25: 4 | H25: 273.25 | I25: 755 Main St | J25: Debit Card | K25: Cancelled | L25: TRK36168083 | M25: 5 | N25: FREESHIP | O25: Referral | P25: 1093 | Q25: 1093 | R25: =IF(OR(P25<Outliers!$B$5, P25>Outliers!$B$6), "outliers", "")
A26: ORD200024 | B26: 45595 | C26: 2024 | D26: Q4 | E26: C17470 | F26: Laptop | G26: 2 | H26: 230.95 | I26: 956 Main St | J26: Online | K26: Delivered | L26: TRK28775057 | M26: 3 | N26: WINTER15 | O26: Referral | P26: 461.9 | Q26: 461.9 | R26: =IF(OR(P26<Outliers!$B$5, P26>Outliers!$B$6), "outliers", "")
A27: ORD200025 | B27: 45497 | C27: 2024 | D27: Q3 | E27: C42577 | F27: Monitor | G27: 1 | H27: 399.98 | I27: 709 Main St | J27: Debit Card | K27: Delivered | L27: TRK69423327 | M27: 3 | N27: WINTER15 | O27: Email | P27: 399.98 | Q27: 399.98 | R27: =IF(OR(P27<Outliers!$B$5, P27>Outliers!$B$6), "outliers", "")
A28: ORD200026 | B28: 45357 | C28: 2024 | D28: Q1 | E28: C21944 | F28: Laptop | G28: 5 | H28: 59.55 | I28: 296 Main St | J28: Online | K28: Delivered | L28: TRK80276812 | M28: 6 | O28: Referral | P28: 297.75 | Q28: 297.75 | R28: =IF(OR(P28<Outliers!$B$5, P28>Outliers!$B$6), "outliers", "")
A29: ORD200027 | B29: 45344 | C29: 2024 | D29: Q1 | E29: C97593 | F29: Printer | G29: 1 | H29: 472.74 | I29: 881 Main St | J29: Online | K29: Shipped | L29: TRK89117573 | M29: 6 | N29: WINTER15 | O29: Google | P29: 472.74 | Q29: 472.74 | R29: =IF(OR(P29<Outliers!$B$5, P29>Outliers!$B$6), "outliers", "")
A30: ORD200028 | B30: 45251 | C30: 2023 | D30: Q4 | E30: C59823 | F30: Phone | G30: 4 | H30: 160.07 | I30: 568 Main St | J30: Online | K30: Pending | L30: TRK65895539 | M30: 5 | O30: Email | P30: 640.28 | Q30: 640.28 | R30: =IF(OR(P30<Outliers!$B$5, P30>Outliers!$B$6), "outliers", "")
A31: ORD200029 | B31: 45555 | C31: 2024 | D31: Q3 | E31: C33260 | F31: Desk | G31: 3 | H31: 423.53 | I31: 930 Main St | J31: Credit Card | K31: Delivered | L31: TRK59744090 | M31: 6 | N31: SAVE10 | O31: Referral | P31: 1270.59 | Q31: 1270.59 | R31: =IF(OR(P31<Outliers!$B$5, P31>Outliers!$B$6), "outliers", "")
A32: ORD200030 | B32: 45738 | C32: 2025 | D32: Q1 | E32: C44267 | F32: Monitor | G32: 2 | H32: 426.7 | I32: 895 Main St | J32: Online | K32: Pending | L32: TRK54751444 | M32: 5 | N32: SAVE10 | O32: Referral | P32: 853.4 | Q32: 853.4 | R32: =IF(OR(P32<Outliers!$B$5, P32>Outliers!$B$6), "outliers", "")
A33: ORD200031 | B33: 45107 | C33: 2023 | D33: Q2 | E33: C26445 | F33: Chair | G33: 3 | H33: 500.08 | I33: 996 Main St | J33: Debit Card | K33: Returned | L33: TRK31229981 | M33: 6 | O33: Facebook | P33: 1500.24 | Q33: 1500.24 | R33: =IF(OR(P33<Outliers!$B$5, P33>Outliers!$B$6), "outliers", "")
A34: ORD200032 | B34: 45047 | C34: 2023 | D34: Q2 | E34: C12388 | F34: Tablet | G34: 5 | H34: 536.72 | I34: 830 Main St | J34: Cash | K34: Delivered | L34: TRK99261395 | M34: 10 | O34: Email | P34: 2683.6 | Q34: 2683.6 | R34: =IF(OR(P34<Outliers!$B$5, P34>Outliers!$B$6), "outliers", "")
A35: ORD200033 | B35: 45082 | C35: 2023 | D35: Q2 | E35: C52184 | F35: Chair | G35: 1 | H35: 162.77 | I35: 912 Main St | J35: Online | K35: Cancelled | L35: TRK73312471 | M35: 4 | N35: WINTER15 | O35: Facebook | P35: 162.77 | Q35: 162.77 | R35: =IF(OR(P35<Outliers!$B$5, P35>Outliers!$B$6), "outliers", "")
A36: ORD200034 | B36: 44933 | C36: 2023 | D36: Q1 | E36: C67195 | F36: Chair | G36: 4 | H36: 576.52 | I36: 926 Main St | J36: Credit Card | K36: Pending | L36: TRK55467915 | M36: 5 | N36: WINTER15 | O36: Facebook | P36: 2306.08 | Q36: 2306.08 | R36: =IF(OR(P36<Outliers!$B$5, P36>Outliers!$B$6), "outliers", "")
A37: ORD200035 | B37: 45633 | C37: 2024 | D37: Q4 | E37: C50304 | F37: Monitor | G37: 2 | H37: 465.15 | I37: 128 Main St | J37: Online | K37: Shipped | L37: TRK46850888 | M37: 2 | N37: SAVE10 | O37: Facebook | P37: 930.3 | Q37: 930.3 | R37: =IF(OR(P37<Outliers!$B$5, P37>Outliers!$B$6), "outliers", "")
A38: ORD200036 | B38: 45785 | C38: 2025 | D38: Q2 | E38: C59337 | F38: Laptop | G38: 2 | H38: 534.43 | I38: 465 Main St | J38: Debit Card | K38: Pending | L38: TRK50961250 | M38: 5 | O38: Facebook | P38: 1068.86 | Q38: 1068.86 | R38: =IF(OR(P38<Outliers!$B$5, P38>Outliers!$B$6), "outliers", "")
A39: ORD200037 | B39: 45579 | C39: 2024 | D39: Q4 | E39: C10054 | F39: Laptop | G39: 2 | H39: 76.74 | I39: 409 Main St | J39: Cash | K39: Returned | L39: TRK94005261 | M39: 7 | N39: SAVE10 | O39: Instagram | P39: 153.48 | Q39: 153.48 | R39: =IF(OR(P39<Outliers!$B$5, P39>Outliers!$B$6), "outliers", "")
A40: ORD200038 | B40: 45645 | C40: 2024 | D40: Q4 | E40: C15924 | F40: Laptop | G40: 1 | H40: 245.89 | I40: 549 Main St | J40: Debit Card | K40: Delivered | L40: TRK14835975 | M40: 3 | N40: SAVE10 | O40: Google | P40: 245.89 | Q40: 245.89 | R40: =IF(OR(P40<Outliers!$B$5, P40>Outliers!$B$6), "outliers", "")
...

Sheet Summary Table
A1: Metric | B1: Mean | C1: Median | D1: Std dev | E1: Min | F1: Max
A2: Quantity | B2: =AVERAGE('Dataset for Data Analytics - cl'!G2:G1201) -> 2.9458333 | C2: =MEDIAN('Dataset for Data Analytics - cl'!G2:G1201) -> 3 | D2: =_xlfn.STDEV.S('Dataset for Data Analytics - cl'!G2:G1201) -> 1.4075571 | E2: =MIN('Dataset for Data Analytics - cl'!G2:G1201) -> 1 | F2: =MAX('Dataset for Data Analytics - cl'!G2:G1201) -> 5
A3: Unitprice | B3: =AVERAGE('Dataset for Data Analytics - cl'!H2:H1201) -> 356.41275 | C3: =MEDIAN('Dataset for Data Analytics - cl'!H2:H1201) -> 364.21 | D3: =_xlfn.STDEV.S('Dataset for Data Analytics - cl'!H2:H1201) -> 197.17715 | E3: =MIN('Dataset for Data Analytics - cl'!H2:H1201) -> 11.39 | F3: =MAX('Dataset for Data Analytics - cl'!H2:H1201) -> 699.93
A4: itemsincart | B4: =AVERAGE('Dataset for Data Analytics - cl'!M2:M1201) -> 5.485 | C4: =MEDIAN('Dataset for Data Analytics - cl'!M2:M1201) -> 5 | D4: =_xlfn.STDEV.S('Dataset for Data Analytics - cl'!M2:M1201) -> 2.2819833 | E4: =MIN('Dataset for Data Analytics - cl'!M2:M1201) -> 1 | F4: =MAX('Dataset for Data Analytics - cl'!M2:M1201) -> 10
A5: Totalprice | B5: =AVERAGE('Dataset for Data Analytics - cl'!P2:P1201) -> 1053.9683 | C5: =MEDIAN('Dataset for Data Analytics - cl'!P2:P1201) -> 823.615 | D5: =_xlfn.STDEV.S('Dataset for Data Analytics - cl'!P2:P1201) -> 819.85656 | E5: =MIN('Dataset for Data Analytics - cl'!P2:P1201) -> 11.39 | F5: =MAX('Dataset for Data Analytics - cl'!P2:P1201) -> 3456.4

Sheet Count Of Product
A3: Products | B3: Count of OrderID
A4: Printer | B4: 181
A5: Tablet | B5: 179
A6: Chair | B6: 178
A7: Laptop | B7: 173
A8: Desk | B8: 170
A9: Monitor | B9: 163
A10: Phone | B10: 156
A11: Grand Total | B11: 1200

Sheet Status Count
A3: Staus | B3: Count of OrderID
A4: Cancelled | B4: 250
A5: Returned | B5: 247
A6: Pending | B6: 237
A7: Shipped | B7: 235
A8: Delivered | B8: 231
A9: Grand Total | B9: 1200

Sheet Referral
A3: Referral | B3: Count of OrderID
A4: Instagram | B4: 259
A5: Email | B5: 250
A6: Google | B6: 241
A7: Facebook | B7: 228
A8: Referral | B8: 222
A9: Grand Total | B9: 1200

Sheet Coupon
A3: Coupon | B3: Count of OrderID
A4: FREESHIP | B4: 313
A5: (blank) | B5: 309
A6: WINTER15 | B6: 292
A7: SAVE10 | B7: 286
A8: Grand Total | B8: 1200

Sheet Payment
A3: Payment | B3: Count of OrderID
A4: Online | B4: 258
A5: Cash | B5: 246
A6: Credit Card | B6: 234
A7: Debit Card | B7: 232
A8: Gift Card | B8: 230
A9: Grand Total | B9: 1200

Sheet Sum
A3: Count of OrderID | B3: Sum of TotalPrice
A4: 1200 | B4: 1264762

Sheet Trend
A3: Date | B3: Sum of TotalPrice
A4: 2023 | B4: 552643.24
A5: Qtr1 | B5: 145412.78
A6: Qtr2 | B6: 141088.74
A7: Qtr3 | B7: 126699.47
A8: Qtr4 | B8: 139442.25
A9: 2024 | B9: 480235.87
A10: Qtr1 | B10: 111468.55
A11: Qtr2 | B11: 145590.79
A12: Qtr3 | B12: 114750.03
A13: Qtr4 | B13: 108426.5
A14: 2025 | B14: 231882.85
A15: Qtr1 | B15: 103617.61
... A17: Grand Total | B17: 1264762

Sheet Outliers
A2: Q1 | B2: =_xlfn.QUARTILE.INC('Dataset for Data Analytics - cl'!P2:P1201, 1) -> 410.52
A3: Q3 | B3: =_xlfn.QUARTILE.INC('Dataset for Data Analytics - cl'!P2:P1201, 3) -> 1578.475
A4: IQR | B4: =B3-B2 -> 1167.955
A5: Lower | B5: =B2-1.5*B4 -> -1341.4125
A6: upper | B6: =B3+1.5*B4 -> 3330.4075
